Workbook

Sheet اكواد الاصناف
A2: كود الصنف | B2: اسم الصنف | C2: الوحدة | D2: السعر
A3: =IF(B3<>"",ROW()-2,"") -> 1 | B3: ارز نور المصطفى طبيعى 25 ك | C3: شيكارة
A4: =IF(B4<>"",ROW()-2,"") -> 2 | B4: ارز نور المصطفى زيت 25 ك | C4: شيكارة
A5: =IF(B5<>"",ROW()-2,"") -> 3 | B5: ارز نور المصطفى طبيعى 10 ك | C5: شيكارة
A6: =IF(B6<>"",ROW()-2,"") -> 4 | B6: ارز نور المصطفى زيت 10 ك | C6: شيكارة
A7: =IF(B7<>"",ROW()-2,"") -> 5 | B7: ارز بسمتي سيلا 10 ك | C7: شيكارة
A8: =IF(B8<>"",ROW()-2,"") -> 6 | B8: ارز بسمتي عروسة 10 ك | C8: شيكارة
A9: =IF(B9<>"",ROW()-2,"") -> 7 | B9: ارز الساعة 1 ك ( كرتونة 10 كيس) | C9: كرتونة
A10: =IF(B10<>"",ROW()-2,"") -> 8 | B10: ارز الساعة 5 ك ( كرتونة 2 كيس ) | C10: كرتونة
A11: =IF(B11<>"",ROW()-2,"") -> 9 | B11: ارز الضحي 1 ك | C11: بالتة
A12: =IF(B12<>"",ROW()-2,"") -> 10 | B12: ارز مليكة 1 ك | C12: بالتة
A13: =IF(B13<>"",ROW()-2,"") -> 11 | B13: سكر معبأ 20 كيس | C13: بالتة
A14: =IF(B14<>"",ROW()-2,"") -> 12 | B14: عدس اصفر معبأ حبة حبة 1 ك | C14: بالتة
... A600: =IF(B600<>"",ROW()-2,"") -> 598 | B600: زيت حلوة 4.5 لتر *2 | C600: كرتونة
A601: =IF(B601<>"",ROW()-2,"")
A602: =IF(B602<>"",ROW()-2,"")
A603: =IF(B603<>"",ROW()-2,"")
A604: =IF(B604<>"",ROW()-2,"")
A605: =IF(B605<>"",ROW()-2,"")
A606: =IF(B606<>"",ROW()-2,"")
A607: =IF(B607<>"",ROW()-2,"")
A608: =IF(B608<>"",ROW()-2,"")
A609: =IF(B609<>"",ROW()-2,"")
A610: =IF(B610<>"",ROW()-2,"")
A611: =IF(B611<>"",ROW()-2,"")
A612: =IF(B612<>"",ROW()-2,"")
... A657: =IF(B657<>"",ROW()-2,"")

Sheet سجل العملاء
A3: كود العميل | B3: اسم العميل | C3: رقم الهاتف | D3: العنوان | E3: هاتف 2 | F3: هاتف 3 | G3: البريد الاليكتروني
A4: =IF(B4<>"",ROW()-3,"") -> 1 | B4: عطارة رؤية | C4: 1271724536 | D4: عزبة محسن
A5: =IF(B5<>"",ROW()-3,"") -> 2 | B5: بازار البوب | C5: 1210604800 | D5: ش الأدوية بجوار كازيون
A6: =IF(B6<>"",ROW()-3,"") -> 3 | B6: مارشيملو ماركت | C6: 1202404095 | D6: ش أحمد تيسير عصافرة
A7: =IF(B7<>"",ROW()-3,"") -> 4 | B7: ابو مصطفى ماركت | C7: 1093011391 | D7: ش 6 اكتوبر اول محسن زقزوق
A8: =IF(B8<>"",ROW()-3,"") -> 5 | B8: بازار المستر | C8: 1152522949 | D8: ش أحمد العوامري متفرع من جمال عبدالناصر ش جزارة السماح والرضا بشر بحري
A9: =IF(B9<>"",ROW()-3,"") -> 6 | B9: ألبان الخير | C9: 1288323473 | D9: ش سيف أمام صيدلية فهمي بشر قبلي
A10: =IF(B10<>"",ROW()-3,"") -> 7 | B10: ام آدم | C10: 1225802667 | D10: خورشيد
A11: =IF(B11<>"",ROW()-3,"") -> 8 | B11: بازار البطل | C11: 1202775100 | D11: ش مسجد عمر بن عبدالعزيز متفرع من عبدالناصر ميامي
A12: =IF(B12<>"",ROW()-3,"") -> 9 | B12: ألبان الشافعي | C12: 1279620525 | D12: ش الأدوية بشر قبلي
A13: =IF(B13<>"",ROW()-3,"") -> 10 | B13: أولاد أشرف عزوز | C13: 1202070691 | D13: ش عزبة النخل خورشيد
A14: =IF(B14<>"",ROW()-3,"") -> 11 | B14: ميدو ماركت | D14: ش الادوية
A15: =IF(B15<>"",ROW()-3,"") -> 12 | B15: عطارة الاخوة | C15: 1013900433 | D15: ش 8 تقاطع الجيش 45 قبلي
A16: =IF(B16<>"",ROW()-3,"") -> 13 | B16: مؤمن العطار | C16: 1158291548 | D16: ش 16 الفلكي
A17: =IF(B17<>"",ROW()-3,"") -> 14 | B17: عطارة الشيخ | C17: 1090530153 | D17: ش عمر بن خيام متفرع من سوق زنانيري
A18: =IF(B18<>"",ROW()-3,"") -> 15 | B18: اولاد شاهين | C18: 1270462298 | D18: عزبة محسن
A19: =IF(B19<>"",ROW()-3,"") -> 16 | B19: نور الاسلام | C19: 1060243702 | D19: الفلكي ش 10 الملك
A20: =IF(B20<>"",ROW()-3,"") -> 17 | B20: حسن العطار | C20: 1099316564 | D20: متفرع من ش حسني المندرة
A21: =IF(B21<>"",ROW()-3,"") -> 18 | B21: عطارة الحواج | C21: 1007578471 | D21: سيدي بشر قبلي
A22: =IF(B22<>"",ROW()-3,"") -> 19 | B22: الوسيم السوري | C22: 1272929351 | D22: المندرة
A23: =IF(B23<>"",ROW()-3,"") -> 20 | B23: ابو مروان | C23: 1226839792 | D23: ش الرحمة خورشيد
A24: =IF(B24<>"",ROW()-3,"") -> 21 | B24: ابو عبدالله | C24: 1212117881 | D24: ش وهران عصافرة
A25: =IF(B25<>"",ROW()-3,"") -> 22 | B25: عطارة الخليفة | C25: 1212117881 | D25: ش عبدالحليم محمود عصافرة
A26: 23 | B26: بيت العروض | C26: 1272773619 | D26: ش الجامع متفرع من خربيتها
A27: 24 | B27: موسي | C27: 1284200543 | D27: شارع السوق خورشيد
A28: 25 | B28: الحرمين ماركت | C28: 1149454907 | D28: ش محمد فريد متفرع من الصفا والمروة 45
A29: 26 | B29: عطارة البيضا عم طلعت | C29: 1067032164 | D29: سوق زنانيري
A30: 27 | B30: ابناء طيبة ماركت | C30: 1111207124 | D30: 182 شارع طيبة بعد تقاطع خضر التوني
A31: =IF(B31<>"",ROW()-3,"") -> 28 | B31: اولاد عاموش | C31: 1097163212 | D31: عزبة محسن
A32: =IF(B32<>"",ROW()-3,"") -> 29 | B32: بلال ماركت | C32: 1007986254 | D32: الفلكى ش 10 الملك
A33: =IF(B33<>"",ROW()-3,"") -> 30 | B33: كينج ماركت كليوباترا | C33: 1211218563 | D33: ش خضر التوني كليوباترا
A34: =IF(B34<>"",ROW()-3,"") -> 31 | B34: ام على | C34: 1286214723 | D34: نمرة 2 متفرع من ش خربتها
A35: =IF(B35<>"",ROW()-3,"") -> 32 | B35: العيلة ماركت | C35: 1288905699 | D35: ش 9 عزبة سكينة
A36: =IF(B36<>"",ROW()-3,"") -> 33 | B36: محمود | C36: 1278063493 | D36: ش الادوية
A37: =IF(B37<>"",ROW()-3,"") -> 34 | B37: زاد الخير | C37: 1209686682 | D37: سيدى بشر
A38: =IF(B38<>"",ROW()-3,"") -> 35 | B38: مينى ماركت السلام | C38: 1124535427 | D38: ش وهران
A39: =IF(B39<>"",ROW()-3,"") -> 36 | B39: الامين ماركت | D39: سيدى بشر ش 62
A40: =IF(B40<>"",ROW()-3,"") -> 37 | B40: بورصة ابو رهف | C40: 1022955851 | D40: ش القاهرة شيدى بشر
A41: =IF(B41<>"",ROW()-3,"") -> 38 | B41: بازار سهيل | C41: 1273171174 | D41: ش سيدى كمال عصافرة
A42: =IF(B42<>"",ROW()-3,"") -> 39 | B42: ابو عمر | C42: 1016245270 | D42: المندرة بحري
...

Sheet سجل الموردين
A3: كود المورد | B3: اسم المورد | C3: رقم الهاتف | D3: العنوان | E3: هاتف 2 | F3: هاتف 3 | G3: البريد الاليكتروني
A4: =IF(B4<>"",ROW()-3,"") -> 1 | B4: شركة البروج للصناعات الغذائية | C4: 1206706540
A5: =IF(B5<>"",ROW()-3,"") -> 2 | B5: شركة نور المصطفى | C5: 1226949663
A6: =IF(B6<>"",ROW()-3,"") -> 3 | B6: شركة المتكاملة | C6: 1223844448
A7: =IF(B7<>"",ROW()-3,"") -> 4 | B7: ايه زد جروب | C7: 1152074440
A8: =IF(B8<>"",ROW()-3,"") -> 5 | B8: شركة الايمان
A9: =IF(B9<>"",ROW()-3,"") -> 6 | B9: مطاحن نوفا
A10: =IF(B10<>"",ROW()-3,"") -> 7 | B10: شركة حواء
A11: =IF(B11<>"",ROW()-3,"") -> 8 | B11: شركة منصور
A12: =IF(B12<>"",ROW()-3,"") -> 9 | B12: الراوى دريم
A13: =IF(B13<>"",ROW()-3,"") -> 10 | B13: مليكة
A14: =IF(B14<>"",ROW()-3,"") -> 11 | B14: هاينز
A15: =IF(B15<>"",ROW()-3,"") -> 12 | B15: شركة ميلانو للاغذية
A16: =IF(B16<>"",ROW()-3,"") -> 13 | B16: شركة حبه حبه
A17: =IF(B17<>"",ROW()-3,"") -> 14 | B17: شركة تايجر
A18: =IF(B18<>"",ROW()-3,"") -> 15 | B18: شركة اندومي
A19: =IF(B19<>"",ROW()-3,"") -> 16 | B19: شركة أبو العلا
... A22: =IF(B22<>"",ROW()-3,"") -> 19 | B22: شركة احمد الشيخ
A23: =IF(B23<>"",ROW()-3,"")
A24: =IF(B24<>"",ROW()-3,"")
A25: =IF(B25<>"",ROW()-3,"")
A26: =IF(B26<>"",ROW()-3,"")
A27: =IF(B27<>"",ROW()-3,"")
A28: =IF(B28<>"",ROW()-3,"")
A29: =IF(B29<>"",ROW()-3,"")
A30: =IF(B30<>"",ROW()-3,"")
A31: =IF(B31<>"",ROW()-3,"")
A32: =IF(B32<>"",ROW()-3,"")
A33: =IF(B33<>"",ROW()-3,"")
A34: =IF(B34<>"",ROW()-3,"")
... A1003: =IF(B1003<>"",ROW()-3,"")

Sheet سجل الوارد 
A1: م | B1: كود الصنف | C1: اسم الصنف | D1: الوحدة | E1: الكمية | F1: السعر | G1: القيمة | H1: كود المورد | I1: اسم المورد | J1: رقم فاتورة الشراء
A2: 1 | B2: 1 | C2: =IFERROR(VLOOKUP(B2,'اكواد الاصناف'!A:B,2,0),"") -> ارز نور المصطفى طبيعى 25 ك | D2: =IFERROR(VLOOKUP(B2,'اكواد الاصناف'!A:C,3,0),"") -> شيكارة | E2: 0 | G2: =E2*F2 -> 0 | I2: =IFERROR(VLOOKUP(H2,'سجل الموردين'!A:B,2,0),"")
A3: 2 | B3: 2 | C3: =IFERROR(VLOOKUP(B3,'اكواد الاصناف'!A:B,2,0),"") -> ارز نور المصطفى زيت 25 ك | D3: =IFERROR(VLOOKUP(B3,'اكواد الاصناف'!A:C,3,0),"") -> شيكارة | E3: 0 | G3: =E3*F3 -> 0 | I3: =IFERROR(VLOOKUP(H3,'سجل الموردين'!A:B,2,0),"")
A4: 3 | B4: 3 | C4: =IFERROR(VLOOKUP(B4,'اكواد الاصناف'!A:B,2,0),"") -> ارز نور المصطفى طبيعى 10 ك | D4: =IFERROR(VLOOKUP(B4,'اكواد الاصناف'!A:C,3,0),"") -> شيكارة | E4: 0 | G4: =E4*F4 -> 0 | I4: =IFERROR(VLOOKUP(H4,'سجل الموردين'!A:B,2,0),"")
A5: 4 | B5: 4 | C5: =IFERROR(VLOOKUP(B5,'اكواد الاصناف'!A:B,2,0),"") -> ارز نور المصطفى زيت 10 ك | D5: =IFERROR(VLOOKUP(B5,'اكواد الاصناف'!A:C,3,0),"") -> شيكارة | E5: 0 | G5: =E5*F5 -> 0 | I5: =IFERROR(VLOOKUP(H5,'سجل الموردين'!A:B,2,0),"")
A6: 5 | B6: 5 | C6: =IFERROR(VLOOKUP(B6,'اكواد الاصناف'!A:B,2,0),"") -> ارز بسمتي سيلا 10 ك | D6: =IFERROR(VLOOKUP(B6,'اكواد الاصناف'!A:C,3,0),"") -> شيكارة | E6: 46 | G6: =E6*F6 -> 0 | I6: =IFERROR(VLOOKUP(H6,'سجل الموردين'!A:B,2,0),"")
A7: 6 | B7: 6 | C7: =IFERROR(VLOOKUP(B7,'اكواد الاصناف'!A:B,2,0),"") -> ارز بسمتي عروسة 10 ك | D7: =IFERROR(VLOOKUP(B7,'اكواد الاصناف'!A:C,3,0),"") -> شيكارة | E7: 54 | G7: =E7*F7 -> 0 | I7: =IFERROR(VLOOKUP(H7,'سجل الموردين'!A:B,2,0),"")
A8: 7 | B8: 7 | C8: =IFERROR(VLOOKUP(B8,'اكواد الاصناف'!A:B,2,0),"") -> ارز الساعة 1 ك ( كرتونة 10 كيس) | D8: =IFERROR(VLOOKUP(B8,'اكواد الاصناف'!A:C,3,0),"") -> كرتونة | E8: 4 | G8: =E8*F8 -> 0 | I8: =IFERROR(VLOOKUP(H8,'سجل الموردين'!A:B,2,0),"")
A9: 8 | B9: 8 | C9: =IFERROR(VLOOKUP(B9,'اكواد الاصناف'!A:B,2,0),"") -> ارز الساعة 5 ك ( كرتونة 2 كيس ) | D9: =IFERROR(VLOOKUP(B9,'اكواد الاصناف'!A:C,3,0),"") -> كرتونة | E9: 2 | G9: =E9*F9 -> 0 | I9: =IFERROR(VLOOKUP(H9,'سجل الموردين'!A:B,2,0),"")
A10: 9 | B10: 9 | C10: =IFERROR(VLOOKUP(B10,'اكواد الاصناف'!A:B,2,0),"") -> ارز الضحي 1 ك | D10: =IFERROR(VLOOKUP(B10,'اكواد الاصناف'!A:C,3,0),"") -> بالتة | E10: 4 | G10: =E10*F10 -> 0 | I10: =IFERROR(VLOOKUP(H10,'سجل الموردين'!A:B,2,0),"")
A11: 10 | B11: 10 | C11: =IFERROR(VLOOKUP(B11,'اكواد الاصناف'!A:B,2,0),"") -> ارز مليكة 1 ك | D11: =IFERROR(VLOOKUP(B11,'اكواد الاصناف'!A:C,3,0),"") -> بالتة | E11: 8 | G11: =E11*F11 -> 0 | I11: =IFERROR(VLOOKUP(H11,'سجل الموردين'!A:B,2,0),"")
A12: 11 | B12: 11 | C12: =IFERROR(VLOOKUP(B12,'اكواد الاصناف'!A:B,2,0),"") -> سكر معبأ 20 كيس | D12: =IFERROR(VLOOKUP(B12,'اكواد الاصناف'!A:C,3,0),"") -> بالتة | E12: 62 | G12: =E12*F12 -> 0 | I12: =IFERROR(VLOOKUP(H12,'سجل الموردين'!A:B,2,0),"")
A13: 12 | B13: 12 | C13: =IFERROR(VLOOKUP(B13,'اكواد الاصناف'!A:B,2,0),"") -> عدس اصفر معبأ حبة حبة 1 ك | D13: =IFERROR(VLOOKUP(B13,'اكواد الاصناف'!A:C,3,0),"") -> بالتة | E13: 0 | G13: =E13*F13 -> 0 | I13: =IFERROR(VLOOKUP(H13,'سجل الموردين'!A:B,2,0),"")
... A446: 445 | B446: 445 | C446: =IFERROR(VLOOKUP(B446,'اكواد الاصناف'!A:B,2,0),"") -> فلفل فيتنامي حصي | D446: =IFERROR(VLOOKUP(B446,'اكواد الاصناف'!A:C,3,0),"") -> كيلو | E446: 215.3 | G446: =E446*F446 -> 0 | I446: =IFERROR(VLOOKUP(H446,'سجل الموردين'!A:B,2,0),"")
A447: 446 | B447: 446 | C447: =IFERROR(VLOOKUP(B447,'اكواد الاصناف'!A:B,2,0),"") -> فلفل فيتنامي ناعم | D447: =IFERROR(VLOOKUP(B447,'اكواد الاصناف'!A:C,3,0),"") -> كيلو | G447: =E447*F447 -> 0 | I447: =IFERROR(VLOOKUP(H447,'سجل الموردين'!A:B,2,0),"")
A448: 447 | B448: 447 | C448: =IFERROR(VLOOKUP(B448,'اكواد الاصناف'!A:B,2,0),"") -> فلفل برازيلي حصي | D448: =IFERROR(VLOOKUP(B448,'اكواد الاصناف'!A:C,3,0),"") -> كيلو | G448: =E448*F448 -> 0 | I448: =IFERROR(VLOOKUP(H448,'سجل الموردين'!A:B,2,0),"")
A449: 448 | B449: 448 | C449: =IFERROR(VLOOKUP(B449,'اكواد الاصناف'!A:B,2,0),"") -> فلفل برازيلي ناعم | D449: =IFERROR(VLOOKUP(B449,'اكواد الاصناف'!A:C,3,0),"") -> كيلو | E449: 0 | G449: =E449*F449 -> 0 | I449: =IFERROR(VLOOKUP(H449,'سجل الموردين'!A:B,2,0),"")
A450: 449 | B450: 449 | C450: =IFERROR(VLOOKUP(B450,'اكواد الاصناف'!A:B,2,0),"") -> كمون بلدي حصي | D450: =IFERROR(VLOOKUP(B450,'اكواد الاصناف'!A:C,3,0),"") -> كيلو | G450: =E450*F450 -> 0 | I450: =IFERROR(VLOOKUP(H450,'سجل الموردين'!A:B,2,0),"")
A451: 450 | B451: 450 | C451: =IFERROR(VLOOKUP(B451,'اكواد الاصناف'!A:B,2,0),"") -> كمون بلدي ناعم | D451: =IFERROR(VLOOKUP(B451,'اكواد الاصناف'!A:C,3,0),"") -> كيلو | G451: =E451*F451 -> 0 | I451: =IFERROR(VLOOKUP(H451,'سجل الموردين'!A:B,2,0),"")
A452: 451 | B452: 451 | C452: =IFERROR(VLOOKUP(B452,'اكواد الاصناف'!A:B,2,0),"") -> كزبرة سوري حصي | D452: =IFERROR(VLOOKUP(B452,'اكواد الاصناف'!A:C,3,0),"") -> كيلو | G452: =E452*F452 -> 0 | I452: =IFERROR(VLOOKUP(H452,'سجل الموردين'!A:B,2,0),"")
A453: 452 | B453: 452 | C453: =IFERROR(VLOOKUP(B453,'اكواد الاصناف'!A:B,2,0),"") -> كزبرة سوري ناعم | D453: =IFERROR(VLOOKUP(B453,'اكواد الاصناف'!A:C,3,0),"") -> كيلو | E453: 0 | G453: =E453*F453 -> 0 | I453: =IFERROR(VLOOKUP(H453,'سجل الموردين'!A:B,2,0),"")
A454: 453 | B454: 453 | C454: =IFERROR(VLOOKUP(B454,'اكواد الاصناف'!A:B,2,0),"") -> كركم هندي ناعم | D454: =IFERROR(VLOOKUP(B454,'اكواد الاصناف'!A:C,3,0),"") -> كيلو | E454: 14 | G454: =E454*F454 -> 0 | I454: =IFERROR(VLOOKUP(H454,'سجل الموردين'!A:B,2,0),"")
A455: 454 | B455: 454 | C455: =IFERROR(VLOOKUP(B455,'اكواد الاصناف'!A:B,2,0),"") -> شمر | D455: =IFERROR(VLOOKUP(B455,'اكواد الاصناف'!A:C,3,0),"") -> كيلو | E455: 0 | G455: =E455*F455 -> 0 | I455: =IFERROR(VLOOKUP(H455,'سجل الموردين'!A:B,2,0),"")
A456: 455 | B456: 455 | C456: =IFERROR(VLOOKUP(B456,'اكواد الاصناف'!A:B,2,0),"") -> ينسون بلدي مغربل | D456: =IFERROR(VLOOKUP(B456,'اكواد الاصناف'!A:C,3,0),"") -> كيلو | E456: 39.7 | G456: =E456*F456 -> 0 | I456: =IFERROR(VLOOKUP(H456,'سجل الموردين'!A:B,2,0),"")
A457: 456 | B457: 456 | C457: =IFERROR(VLOOKUP(B457,'اكواد الاصناف'!A:B,2,0),"") -> ينسون نجمة | D457: =IFERROR(VLOOKUP(B457,'اكواد الاصناف'!A:C,3,0),"") -> كيلو | E457: 0 | G457: =E457*F457 -> 0 | I457: =IFERROR(VLOOKUP(H457,'سجل الموردين'!A:B,2,0),"")
A458: 457 | B458: 457 | C458: =IFERROR(VLOOKUP(B458,'اكواد الاصناف'!A:B,2,0),"") -> حبة البركة | D458: =IFERROR(VLOOKUP(B458,'اكواد الاصناف'!A:C,3,0),"") -> كيلو | E458: 4.5 | G458: =E458*F458 -> 0 | I458: =IFERROR(VLOOKUP(H458,'سجل الموردين'!A:B,2,0),"")
A459: 458 | B459: 458 | C459: =IFERROR(VLOOKUP(B459,'اكواد الاصناف'!A:B,2,0),"") -> جوزة الطيب | D459: =IFERROR(VLOOKUP(B459,'اكواد الاصناف'!A:C,3,0),"") -> كيلو | E459: 0 | G459: =E459*F459 -> 0 | I459: =IFERROR(VLOOKUP(H459,'سجل الموردين'!A:B,2,0),"")
A460: 459 | B460: 459 | C460: =IFERROR(VLOOKUP(B460,'اكواد الاصناف'!A:B,2,0),"") -> حبهان وسط | D460: =IFERROR(VLOOKUP(B460,'اكواد الاصناف'!A:C,3,0),"") -> كيلو | E460: 0 | G460: =E460*F460 -> 0 | I460: =IFERROR(VLOOKUP(H460,'سجل الموردين'!A:B,2,0),"")
A461: 460 | B461: 460 | C461: =IFERROR(VLOOKUP(B461,'اكواد الاصناف'!A:B,2,0),"") -> قرفة سيجار | D461: =IFERROR(VLOOKUP(B461,'اكواد الاصناف'!A:C,3,0),"") -> كيلو | E461: 12 | G461: =E461*F461 -> 0 | I461: =IFERROR(VLOOKUP(H461,'سجل الموردين'!A:B,2,0),"")
A462: 461 | B462: 461 | C462: =IFERROR(VLOOKUP(B462,'اكواد الاصناف'!A:B,2,0),"") -> قرفة ناعمه | D462: =IFERROR(VLOOKUP(B462,'اكواد الاصناف'!A:C,3,0),"") -> كيلو | E462: 14 | G462: =E462*F462 -> 0 | I462: =IFERROR(VLOOKUP(H462,'سجل الموردين'!A:B,2,0),"")
A463: 462 | B463: 462 | C463: =IFERROR(VLOOKUP(B463,'اكواد الاصناف'!A:B,2,0),"") -> ورق لوري مقرطف | D463: =IFERROR(VLOOKUP(B463,'اكواد الاصناف'!A:C,3,0),"") -> كيلو | E463: 5.9 | G463: =E463*F463 -> 0 | I463: =IFERROR(VLOOKUP(H463,'سجل الموردين'!A:B,2,0),"")
A464: 463 | B464: 463 | C464: =IFERROR(VLOOKUP(B464,'اكواد الاصناف'!A:B,2,0),"") -> ليمون ناشف أسود | D464: =IFERROR(VLOOKUP(B464,'اكواد الاصناف'!A:C,3,0),"") -> كيلو | E464: 17 | G464: =E464*F464 -> 0 | I464: =IFERROR(VLOOKUP(H464,'سجل الموردين'!A:B,2,0),"")
... A467: 466 | B467: 466 | C467: =IFERROR(VLOOKUP(B467,'اكواد الاصناف'!A:B,2,0),"") -> سلمكة قرن | D467: =IFERROR(VLOOKUP(B467,'اكواد الاصناف'!A:C,3,0),"") -> كيلو | E467: 0 | G467: =E467*F467 -> 0 | I467: =IFERROR(VLOOKUP(H467,'سجل الموردين'!A:B,2,0),"")
A468: 467 | B468: 467 | C468: =IFERROR(VLOOKUP(B468,'اكواد الاصناف'!A:B,2,0),"") -> زنجبيل ناعم | D468: =IFERROR(VLOOKUP(B468,'اكواد الاصناف'!A:C,3,0),"") -> كيلو | G468: =E468*F468 -> 0 | I468: =IFERROR(VLOOKUP(H468,'سجل الموردين'!A:B,2,0),"")
A469: 468 | B469: 468 | C469: =IFERROR(VLOOKUP(B469,'اكواد الاصناف'!A:B,2,0),"") -> روزماري (حصي لبان 1) | D469: =IFERROR(VLOOKUP(B469,'اكواد الاصناف'!A:C,3,0),"") -> كيلو | E469: 0 | G469: =E469*F469 -> 0 | I469: =IFERROR(VLOOKUP(H469,'سجل الموردين'!A:B,2,0),"")
A470: 469 | B470: 469 | C470: =IFERROR(VLOOKUP(B470,'اكواد الاصناف'!A:B,2,0),"") -> بردقوش | D470: =IFERROR(VLOOKUP(B470,'اكواد الاصناف'!A:C,3,0),"") -> كيلو | E470: 0 | G470: =E470*F470 -> 0 | I470: =IFERROR(VLOOKUP(H470,'سجل الموردين'!A:B,2,0),"")
A471: 470 | B471: 470 | C471: =IFERROR(VLOOKUP(B471,'اكواد الاصناف'!A:B,2,0),"") -> زعتر بلدي أخضر وسط | D471: =IFERROR(VLOOKUP(B471,'اكواد الاصناف'!A:C,3,0),"") -> كيلو | E471: 0 | G471: =E471*F471 -> 0 | I471: =IFERROR(VLOOKUP(H471,'سجل الموردين'!A:B,2,0),"")
A472: 471 | B472: 471 | C472: =IFERROR(VLOOKUP(B472,'اكواد الاصناف'!A:B,2,0),"") -> زر ورد باكستاني | D472: =IFERROR(VLOOKUP(B472,'اكواد الاصناف'!A:C,3,0),"") -> كيلو | E472: 0 | G472: =E472*F472 -> 0 | I472: =IFERROR(VLOOKUP(H472,'سجل الموردين'!A:B,2,0),"")
A473: 472 | B473: 472 | C473: =IFERROR(VLOOKUP(B473,'اكواد الاصناف'!A:B,2,0),"") -> ببريكا صيني | D473: =IFERROR(VLOOKUP(B473,'اكواد الاصناف'!A:C,3,0),"") -> كيلو | E473: 13 | G473: =E473*F473 -> 0 | I473: =IFERROR(VLOOKUP(H473,'سجل الموردين'!A:B,2,0),"")
A474: 473 | B474: 473 | C474: =IFERROR(VLOOKUP(B474,'اكواد الاصناف'!A:B,2,0),"") -> كربوناته تركي | D474: =IFERROR(VLOOKUP(B474,'اكواد الاصناف'!A:C,3,0),"") -> كيلو | G474: =E474*F474 -> 0 | I474: =IFERROR(VLOOKUP(H474,'سجل الموردين'!A:B,2,0),"")
...

Sheet رصيد المخازن
D2: نوع الحركة
A3: كود الصنف | B3: اسم الصنف | C3: الوحدة | D3: إضافة للمخزن | E3: منصرف | F3: الرصيد
A4: 1 | B4: =IFERROR(VLOOKUP(A4,'اكواد الاصناف'!A:B,2,0),"") -> ارز نور المصطفى طبيعى 25 ك | C4: =IFERROR(VLOOKUP(A4,'اكواد الاصناف'!A:C,3,0),"") -> شيكارة | D4: =SUMIF('سجل الوارد '!B:B,A4,'سجل الوارد '!E:E) -> 0 | E4: =IF(SUMIF('سجل المبيعات'!B:B,A4,'سجل المبيعات'!E:E)<=0,"",SUMIF('سجل المبيعات'!B:B,A4,'سجل المبيعات'!E:E)) | F4: =IFERROR(D4-E4,"")
A5: 2 | B5: =IFERROR(VLOOKUP(A5,'اكواد الاصناف'!A:B,2,0),"") -> ارز نور المصطفى زيت 25 ك | C5: =IFERROR(VLOOKUP(A5,'اكواد الاصناف'!A:C,3,0),"") -> شيكارة | D5: =SUMIF('سجل الوارد '!B:B,A5,'سجل الوارد '!E:E) -> 0 | E5: =IF(SUMIF('سجل المبيعات'!B:B,A5,'سجل المبيعات'!E:E)<=0,"",SUMIF('سجل المبيعات'!B:B,A5,'سجل المبيعات'!E:E)) | F5: =IFERROR(D5-E5,"")
A6: 3 | B6: =IFERROR(VLOOKUP(A6,'اكواد الاصناف'!A:B,2,0),"") -> ارز نور المصطفى طبيعى 10 ك | C6: =IFERROR(VLOOKUP(A6,'اكواد الاصناف'!A:C,3,0),"") -> شيكارة | D6: =SUMIF('سجل الوارد '!B:B,A6,'سجل الوارد '!E:E) -> 0 | E6: =IF(SUMIF('سجل المبيعات'!B:B,A6,'سجل المبيعات'!E:E)<=0,"",SUMIF('سجل المبيعات'!B:B,A6,'سجل المبيعات'!E:E)) | F6: =IFERROR(D6-E6,"")
A7: 4 | B7: =IFERROR(VLOOKUP(A7,'اكواد الاصناف'!A:B,2,0),"") -> ارز نور المصطفى زيت 10 ك | C7: =IFERROR(VLOOKUP(A7,'اكواد الاصناف'!A:C,3,0),"") -> شيكارة | D7: =SUMIF('سجل الوارد '!B:B,A7,'سجل الوارد '!E:E) -> 0 | E7: =IF(SUMIF('سجل المبيعات'!B:B,A7,'سجل المبيعات'!E:E)<=0,"",SUMIF('سجل المبيعات'!B:B,A7,'سجل المبيعات'!E:E)) | F7: =IFERROR(D7-E7,"")
A8: 5 | B8: =IFERROR(VLOOKUP(A8,'اكواد الاصناف'!A:B,2,0),"") -> ارز بسمتي سيلا 10 ك | C8: =IFERROR(VLOOKUP(A8,'اكواد الاصناف'!A:C,3,0),"") -> شيكارة | D8: =SUMIF('سجل الوارد '!B:B,A8,'سجل الوارد '!E:E) -> 46 | E8: =IF(SUMIF('سجل المبيعات'!B:B,A8,'سجل المبيعات'!E:E)<=0,"",SUMIF('سجل المبيعات'!B:B,A8,'سجل المبيعات'!E:E)) -> 6 | F8: =IFERROR(D8-E8,"") -> 40
A9: 6 | B9: =IFERROR(VLOOKUP(A9,'اكواد الاصناف'!A:B,2,0),"") -> ارز بسمتي عروسة 10 ك | C9: =IFERROR(VLOOKUP(A9,'اكواد الاصناف'!A:C,3,0),"") -> شيكارة | D9: =SUMIF('سجل الوارد '!B:B,A9,'سجل الوارد '!E:E) -> 54 | E9: =IF(SUMIF('سجل المبيعات'!B:B,A9,'سجل المبيعات'!E:E)<=0,"",SUMIF('سجل المبيعات'!B:B,A9,'سجل المبيعات'!E:E)) -> 15 | F9: =IFERROR(D9-E9,"") -> 39
A10: 7 | B10: =IFERROR(VLOOKUP(A10,'اكواد الاصناف'!A:B,2,0),"") -> ارز الساعة 1 ك ( كرتونة 10 كيس) | C10: =IFERROR(VLOOKUP(A10,'اكواد الاصناف'!A:C,3,0),"") -> كرتونة | D10: =SUMIF('سجل الوارد '!B:B,A10,'سجل الوارد '!E:E) -> 14 | E10: =IF(SUMIF('سجل المبيعات'!B:B,A10,'سجل المبيعات'!E:E)<=0,"",SUMIF('سجل المبيعات'!B:B,A10,'سجل المبيعات'!E:E)) -> 11 | F10: =IFERROR(D10-E10,"") -> 3
A11: 8 | B11: =IFERROR(VLOOKUP(A11,'اكواد الاصناف'!A:B,2,0),"") -> ارز الساعة 5 ك ( كرتونة 2 كيس ) | C11: =IFERROR(VLOOKUP(A11,'اكواد الاصناف'!A:C,3,0),"") -> كرتونة | D11: =SUMIF('سجل الوارد '!B:B,A11,'سجل الوارد '!E:E) -> 2 | E11: =IF(SUMIF('سجل المبيعات'!B:B,A11,'سجل المبيعات'!E:E)<=0,"",SUMIF('سجل المبيعات'!B:B,A11,'سجل المبيعات'!E:E)) | F11: =IFERROR(D11-E11,"")
A12: 9 | B12: =IFERROR(VLOOKUP(A12,'اكواد الاصناف'!A:B,2,0),"") -> ارز الضحي 1 ك | C12: =IFERROR(VLOOKUP(A12,'اكواد الاصناف'!A:C,3,0),"") -> بالتة | D12: =SUMIF('سجل الوارد '!B:B,A12,'سجل الوارد '!E:E) -> 10 | E12: =IF(SUMIF('سجل المبيعات'!B:B,A12,'سجل المبيعات'!E:E)<=0,"",SUMIF('سجل المبيعات'!B:B,A12,'سجل المبيعات'!E:E)) -> 4 | F12: =IFERROR(D12-E12,"") -> 6
A13: 10 | B13: =IFERROR(VLOOKUP(A13,'اكواد الاصناف'!A:B,2,0),"") -> ارز مليكة 1 ك | C13: =IFERROR(VLOOKUP(A13,'اكواد الاصناف'!A:C,3,0),"") -> بالتة | D13: =SUMIF('سجل الوارد '!B:B,A13,'سجل الوارد '!E:E) -> 8 | E13: =IF(SUMIF('سجل المبيعات'!B:B,A13,'سجل المبيعات'!E:E)<=0,"",SUMIF('سجل المبيعات'!B:B,A13,'سجل المبيعات'!E:E)) -> 3 | F13: =IFERROR(D13-E13,"") -> 5
A14: 11 | B14: =IFERROR(VLOOKUP(A14,'اكواد الاصناف'!A:B,2,0),"") -> سكر معبأ 20 كيس | C14: =IFERROR(VLOOKUP(A14,'اكواد الاصناف'!A:C,3,0),"") -> بالتة | D14: =SUMIF('سجل الوارد '!B:B,A14,'سجل الوارد '!E:E) -> 62 | E14: =IF(SUMIF('سجل المبيعات'!B:B,A14,'سجل المبيعات'!E:E)<=0,"",SUMIF('سجل المبيعات'!B:B,A14,'سجل المبيعات'!E:E)) -> 39 | F14: =IFERROR(D14-E14,"") -> 23
A15: 12 | B15: =IFERROR(VLOOKUP(A15,'اكواد الاصناف'!A:B,2,0),"") -> عدس اصفر معبأ حبة حبة 1 ك | C15: =IFERROR(VLOOKUP(A15,'اكواد الاصناف'!A:C,3,0),"") -> بالتة | D15: =SUMIF('سجل الوارد '!B:B,A15,'سجل الوارد '!E:E) -> 0 | E15: =IF(SUMIF('سجل المبيعات'!B:B,A15,'سجل المبيعات'!E:E)<=0,"",SUMIF('سجل المبيعات'!B:B,A15,'سجل المبيعات'!E:E)) | F15: =IFERROR(D15-E15,"")
... A601: 598 | B601: =IFERROR(VLOOKUP(A601,'اكواد الاصناف'!A:B,2,0),"") -> زيت حلوة 4.5 لتر *2 | C601: =IFERROR(VLOOKUP(A601,'اكواد الاصناف'!A:C,3,0),"") -> كرتونة | D601: =SUMIF('سجل الوارد '!B:B,A601,'سجل الوارد '!E:E) -> 3 | E601: =IF(SUMIF('سجل المبيعات'!B:B,A601,'سجل المبيعات'!E:E)<=0,"",SUMIF('سجل المبيعات'!B:B,A601,'سجل المبيعات'!E:E)) -> 2 | F601: =IFERROR(D601-E601,"") -> 1
B602: =IFERROR(VLOOKUP(A602,'اكواد الاصناف'!A:B,2,0),"") | C602: =IFERROR(VLOOKUP(A602,'اكواد الاصناف'!A:C,3,0),"") | D602: =SUMIF('سجل الوارد '!B:B,A602,'سجل الوارد '!E:E) -> 0 | E602: =IF(SUMIF('سجل المبيعات'!B:B,A602,'سجل المبيعات'!E:E)<=0,"",SUMIF('سجل المبيعات'!B:B,A602,'سجل المبيعات'!E:E)) | F602: =IFERROR(D602-E602,"")
B603: =IFERROR(VLOOKUP(A603,'اكواد الاصناف'!A:B,2,0),"") | C603: =IFERROR(VLOOKUP(A603,'اكواد الاصناف'!A:C,3,0),"") | D603: =SUMIF('سجل الوارد '!B:B,A603,'سجل الوارد '!E:E) -> 0 | E603: =IF(SUMIF('سجل المبيعات'!B:B,A603,'سجل المبيعات'!E:E)<=0,"",SUMIF('سجل المبيعات'!B:B,A603,'سجل المبيعات'!E:E)) | F603: =IFERROR(D603-E603,"")
B604: =IFERROR(VLOOKUP(A604,'اكواد الاصناف'!A:B,2,0),"") | C604: =IFERROR(VLOOKUP(A604,'اكواد الاصناف'!A:C,3,0),"") | D604: =SUMIF('سجل الوارد '!B:B,A604,'سجل الوارد '!E:E) -> 0 | E604: =IF(SUMIF('سجل المبيعات'!B:B,A604,'سجل المبيعات'!E:E)<=0,"",SUMIF('سجل المبيعات'!B:B,A604,'سجل المبيعات'!E:E)) | F604: =IFERROR(D604-E604,"")
B605: =IFERROR(VLOOKUP(A605,'اكواد الاصناف'!A:B,2,0),"") | C605: =IFERROR(VLOOKUP(A605,'اكواد الاصناف'!A:C,3,0),"") | D605: =SUMIF('سجل الوارد '!B:B,A605,'سجل الوارد '!E:E) -> 0 | E605: =IF(SUMIF('سجل المبيعات'!B:B,A605,'سجل المبيعات'!E:E)<=0,"",SUMIF('سجل المبيعات'!B:B,A605,'سجل المبيعات'!E:E)) | F605: =IFERROR(D605-E605,"")
B606: =IFERROR(VLOOKUP(A606,'اكواد الاصناف'!A:B,2,0),"") | C606: =IFERROR(VLOOKUP(A606,'اكواد الاصناف'!A:C,3,0),"") | D606: =SUMIF('سجل الوارد '!B:B,A606,'سجل الوارد '!E:E) -> 0 | E606: =IF(SUMIF('سجل المبيعات'!B:B,A606,'سجل المبيعات'!E:E)<=0,"",SUMIF('سجل المبيعات'!B:B,A606,'سجل المبيعات'!E:E)) | F606: =IFERROR(D606-E606,"")
B607: =IFERROR(VLOOKUP(A607,'اكواد الاصناف'!A:B,2,0),"") | C607: =IFERROR(VLOOKUP(A607,'اكواد الاصناف'!A:C,3,0),"") | D607: =SUMIF('سجل الوارد '!B:B,A607,'سجل الوارد '!E:E) -> 0 | E607: =IF(SUMIF('سجل المبيعات'!B:B,A607,'سجل المبيعات'!E:E)<=0,"",SUMIF('سجل المبيعات'!B:B,A607,'سجل المبيعات'!E:E)) | F607: =IFERROR(D607-E607,"")
B608: =IFERROR(VLOOKUP(A608,'اكواد الاصناف'!A:B,2,0),"") | C608: =IFERROR(VLOOKUP(A608,'اكواد الاصناف'!A:C,3,0),"") | D608: =SUMIF('سجل الوارد '!B:B,A608,'سجل الوارد '!E:E) -> 0 | E608: =IF(SUMIF('سجل المبيعات'!B:B,A608,'سجل المبيعات'!E:E)<=0,"",SUMIF('سجل المبيعات'!B:B,A608,'سجل المبيعات'!E:E)) | F608: =IFERROR(D608-E608,"")
B609: =IFERROR(VLOOKUP(A609,'اكواد الاصناف'!A:B,2,0),"") | C609: =IFERROR(VLOOKUP(A609,'اكواد الاصناف'!A:C,3,0),"") | D609: =SUMIF('سجل الوارد '!B:B,A609,'سجل الوارد '!E:E) -> 0 | E609: =IF(SUMIF('سجل المبيعات'!B:B,A609,'سجل المبيعات'!E:E)<=0,"",SUMIF('سجل المبيعات'!B:B,A609,'سجل المبيعات'!E:E)) | F609: =IFERROR(D609-E609,"")
B610: =IFERROR(VLOOKUP(A610,'اكواد الاصناف'!A:B,2,0),"") | C610: =IFERROR(VLOOKUP(A610,'اكواد الاصناف'!A:C,3,0),"") | D610: =SUMIF('سجل الوارد '!B:B,A610,'سجل الوارد '!E:E) -> 0 | E610: =IF(SUMIF('سجل المبيعات'!B:B,A610,'سجل المبيعات'!E:E)<=0,"",SUMIF('سجل المبيعات'!B:B,A610,'سجل المبيعات'!E:E)) | F610: =IFERROR(D610-E610,"")
B611: =IFERROR(VLOOKUP(A611,'اكواد الاصناف'!A:B,2,0),"") | C611: =IFERROR(VLOOKUP(A611,'اكواد الاصناف'!A:C,3,0),"") | D611: =SUMIF('سجل الوارد '!B:B,A611,'سجل الوارد '!E:E) -> 0 | E611: =IF(SUMIF('سجل المبيعات'!B:B,A611,'سجل المبيعات'!E:E)<=0,"",SUMIF('سجل المبيعات'!B:B,A611,'سجل المبيعات'!E:E)) | F611: =IFERROR(D611-E611,"")
B612: =IFERROR(VLOOKUP(A612,'اكواد الاصناف'!A:B,2,0),"") | C612: =IFERROR(VLOOKUP(A612,'اكواد الاصناف'!A:C,3,0),"") | D612: =SUMIF('سجل الوارد '!B:B,A612,'سجل الوارد '!E:E) -> 0 | E612: =IF(SUMIF('سجل المبيعات'!B:B,A612,'سجل المبيعات'!E:E)<=0,"",SUMIF('سجل المبيعات'!B:B,A612,'سجل المبيعات'!E:E)) | F612: =IFERROR(D612-E612,"")
B613: =IFERROR(VLOOKUP(A613,'اكواد الاصناف'!A:B,2,0),"") | C613: =IFERROR(VLOOKUP(A613,'اكواد الاصناف'!A:C,3,0),"") | D613: =SUMIF('سجل الوارد '!B:B,A613,'سجل الوارد '!E:E) -> 0 | E613: =IF(SUMIF('سجل المبيعات'!B:B,A613,'سجل المبيعات'!E:E)<=0,"",SUMIF('سجل المبيعات'!B:B,A613,'سجل المبيعات'!E:E)) | F613: =IFERROR(D613-E613,"")
... B1623: =IFERROR(VLOOKUP(A1623,'اكواد الاصناف'!A:B,2,0),"") | C1623: =IFERROR(VLOOKUP(A1623,'اكواد الاصناف'!A:C,3,0),"") | D1623: =SUMIF('سجل الوارد '!B:B,A1623,'سجل الوارد '!E:E) -> 0 | E1623: =IF(SUMIF('سجل المبيعات'!B:B,A1623,'سجل المبيعات'!E:E)<=0,"",SUMIF('سجل المبيعات'!B:B,A1623,'سجل المبيعات'!E:E)) | F1623: =IFERROR(D1623-E1623,"")

Sheet فواتير
C3: اذن صرف | G3: 564
F4: نظام الدفع :
A5: شركة | B5: ابو رؤية للتجارة والتوزيع
F6: تاريخ | G6: =TODAY() -> 46181
A7: كود العميل | F7: المندوب
A8: اسم العميل | B8: =IFERROR(VLOOKUP(B7,'سجل العملاء'!A:B,2,0),"") | F8: ت : | G8: =IFERROR(VLOOKUP(B7,'سجل العملاء'!A:C,3,0),"")
A9: العنوان | B9: =IFERROR(VLOOKUP(B7,'سجل العملاء'!A:D,4,0),"")
A10: م | B10: كود الصنف | C10: اسم الصنف | D10: الوحدة | E10: الكمية | F10: السعر | G10: القيمة
A11: 1 | C11: =IFERROR(VLOOKUP(Table3[[#This Row],[كود الصنف]],'اكواد الاصناف'!A:C,2,0),"") | D11: =IFERROR(VLOOKUP(Table3[[#This Row],[كود الصنف]],'اكواد الاصناف'!A:C,3,0),"") | F11: =IF(SUMIF('اكواد الاصناف'!A:A,Table3[[#This Row],[كود الصنف]],'اكواد الاصناف'!D:D)=0,"",SUMIF('اكواد الاصناف'!A:A,Table3[[#This Row],[كود الصنف]],'اكواد الاصناف'!D:D)) | G11: =IFERROR(IF(Table3[[#This Row],[السعر]]*Table3[[#This Row],[الكمية]]<=0,"",Table3[[#This Row],[السعر]]*Table3[[#This Row],[الكمية]]),"")
A12: 2 | C12: =IFERROR(VLOOKUP(Table3[[#This Row],[كود الصنف]],'اكواد الاصناف'!A:C,2,0),"") | D12: =IFERROR(VLOOKUP(Table3[[#This Row],[كود الصنف]],'اكواد الاصناف'!A:C,3,0),"") | F12: =IF(SUMIF('اكواد الاصناف'!A:A,Table3[[#This Row],[كود الصنف]],'اكواد الاصناف'!D:D)=0,"",SUMIF('اكواد الاصناف'!A:A,Table3[[#This Row],[كود الصنف]],'اكواد الاصناف'!D:D)) | G12: =IFERROR(IF(Table3[[#This Row],[السعر]]*Table3[[#This Row],[الكمية]]<=0,"",Table3[[#This Row],[السعر]]*Table3[[#This Row],[الكمية]]),"")
A13: 3 | C13: =IFERROR(VLOOKUP(Table3[[#This Row],[كود الصنف]],'اكواد الاصناف'!A:C,2,0),"") | D13: =IFERROR(VLOOKUP(Table3[[#This Row],[كود الصنف]],'اكواد الاصناف'!A:C,3,0),"") | F13: =IF(SUMIF('اكواد الاصناف'!A:A,Table3[[#This Row],[كود الصنف]],'اكواد الاصناف'!D:D)=0,"",SUMIF('اكواد الاصناف'!A:A,Table3[[#This Row],[كود الصنف]],'اكواد الاصناف'!D:D)) | G13: =IFERROR(IF(Table3[[#This Row],[السعر]]*Table3[[#This Row],[الكمية]]<=0,"",Table3[[#This Row],[السعر]]*Table3[[#This Row],[الكمية]]),"")
A14: 4 | C14: =IFERROR(VLOOKUP(Table3[[#This Row],[كود الصنف]],'اكواد الاصناف'!A:C,2,0),"") | D14: =IFERROR(VLOOKUP(Table3[[#This Row],[كود الصنف]],'اكواد الاصناف'!A:C,3,0),"") | F14: =IF(SUMIF('اكواد الاصناف'!A:A,Table3[[#This Row],[كود الصنف]],'اكواد الاصناف'!D:D)=0,"",SUMIF('اكواد الاصناف'!A:A,Table3[[#This Row],[كود الصنف]],'اكواد الاصناف'!D:D)) | G14: =IFERROR(IF(Table3[[#This Row],[السعر]]*Table3[[#This Row],[الكمية]]<=0,"",Table3[[#This Row],[السعر]]*Table3[[#This Row],[الكمية]]),"")
A15: 5 | C15: =IFERROR(VLOOKUP(Table3[[#This Row],[كود الصنف]],'اكواد الاصناف'!A:C,2,0),"") | D15: =IFERROR(VLOOKUP(Table3[[#This Row],[كود الصنف]],'اكواد الاصناف'!A:C,3,0),"") | F15: =IF(SUMIF('اكواد الاصناف'!A:A,Table3[[#This Row],[كود الصنف]],'اكواد الاصناف'!D:D)=0,"",SUMIF('اكواد الاصناف'!A:A,Table3[[#This Row],[كود الصنف]],'اكواد الاصناف'!D:D)) | G15: =IFERROR(IF(Table3[[#This Row],[السعر]]*Table3[[#This Row],[الكمية]]<=0,"",Table3[[#This Row],[السعر]]*Table3[[#This Row],[الكمية]]),"")
A16: 6 | C16: =IFERROR(VLOOKUP(Table3[[#This Row],[كود الصنف]],'اكواد الاصناف'!A:C,2,0),"") | D16: =IFERROR(VLOOKUP(Table3[[#This Row],[كود الصنف]],'اكواد الاصناف'!A:C,3,0),"") | F16: =IF(SUMIF('اكواد الاصناف'!A:A,Table3[[#This Row],[كود الصنف]],'اكواد الاصناف'!D:D)=0,"",SUMIF('اكواد الاصناف'!A:A,Table3[[#This Row],[كود الصنف]],'اكواد الاصناف'!D:D)) | G16: =IFERROR(IF(Table3[[#This Row],[السعر]]*Table3[[#This Row],[الكمية]]<=0,"",Table3[[#This Row],[السعر]]*Table3[[#This Row],[الكمية]]),"")
A17: 7 | C17: =IFERROR(VLOOKUP(Table3[[#This Row],[كود الصنف]],'اكواد الاصناف'!A:C,2,0),"") | D17: =IFERROR(VLOOKUP(Table3[[#This Row],[كود الصنف]],'اكواد الاصناف'!A:C,3,0),"") | F17: =IF(SUMIF('اكواد الاصناف'!A:A,Table3[[#This Row],[كود الصنف]],'اكواد الاصناف'!D:D)=0,"",SUMIF('اكواد الاصناف'!A:A,Table3[[#This Row],[كود الصنف]],'اكواد الاصناف'!D:D)) | G17: =IFERROR(IF(Table3[[#This Row],[السعر]]*Table3[[#This Row],[الكمية]]<=0,"",Table3[[#This Row],[السعر]]*Table3[[#This Row],[الكمية]]),"")
A18: 8 | C18: =IFERROR(VLOOKUP(Table3[[#This Row],[كود الصنف]],'اكواد الاصناف'!A:C,2,0),"") | D18: =IFERROR(VLOOKUP(Table3[[#This Row],[كود الصنف]],'اكواد الاصناف'!A:C,3,0),"") | F18: =IF(SUMIF('اكواد الاصناف'!A:A,Table3[[#This Row],[كود الصنف]],'اكواد الاصناف'!D:D)=0,"",SUMIF('اكواد الاصناف'!A:A,Table3[[#This Row],[كود الصنف]],'اكواد الاصناف'!D:D)) | G18: =IFERROR(IF(Table3[[#This Row],[السعر]]*Table3[[#This Row],[الكمية]]<=0,"",Table3[[#This Row],[السعر]]*Table3[[#This Row],[الكمية]]),"")
A19: 9 | C19: =IFERROR(VLOOKUP(Table3[[#This Row],[كود الصنف]],'اكواد الاصناف'!A:C,2,0),"") | D19: =IFERROR(VLOOKUP(Table3[[#This Row],[كود الصنف]],'اكواد الاصناف'!A:C,3,0),"") | F19: =IF(SUMIF('اكواد الاصناف'!A:A,Table3[[#This Row],[كود الصنف]],'اكواد الاصناف'!D:D)=0,"",SUMIF('اكواد الاصناف'!A:A,Table3[[#This Row],[كود الصنف]],'اكواد الاصناف'!D:D)) | G19: =IFERROR(IF(Table3[[#This Row],[السعر]]*Table3[[#This Row],[الكمية]]<=0,"",Table3[[#This Row],[السعر]]*Table3[[#This Row],[الكمية]]),"")
A20: 10 | C20: =IFERROR(VLOOKUP(Table3[[#This Row],[كود الصنف]],'اكواد الاصناف'!A:C,2,0),"") | D20: =IFERROR(VLOOKUP(Table3[[#This Row],[كود الصنف]],'اكواد الاصناف'!A:C,3,0),"") | F20: =IF(SUMIF('اكواد الاصناف'!A:A,Table3[[#This Row],[كود الصنف]],'اكواد الاصناف'!D:D)=0,"",SUMIF('اكواد الاصناف'!A:A,Table3[[#This Row],[كود الصنف]],'اكواد الاصناف'!D:D)) | G20: =IFERROR(IF(Table3[[#This Row],[السعر]]*Table3[[#This Row],[الكمية]]<=0,"",Table3[[#This Row],[السعر]]*Table3[[#This Row],[الكمية]]),"")
A21: 11 | C21: =IFERROR(VLOOKUP(Table3[[#This Row],[كود الصنف]],'اكواد الاصناف'!A:C,2,0),"") | D21: =IFERROR(VLOOKUP(Table3[[#This Row],[كود الصنف]],'اكواد الاصناف'!A:C,3,0),"") | F21: =IF(SUMIF('اكواد الاصناف'!A:A,Table3[[#This Row],[كود الصنف]],'اكواد الاصناف'!D:D)=0,"",SUMIF('اكواد الاصناف'!A:A,Table3[[#This Row],[كود الصنف]],'اكواد الاصناف'!D:D)) | G21: =IFERROR(IF(Table3[[#This Row],[السعر]]*Table3[[#This Row],[الكمية]]<=0,"",Table3[[#This Row],[السعر]]*Table3[[#This Row],[الكمية]]),"")
A22: 12 | C22: =IFERROR(VLOOKUP(Table3[[#This Row],[كود الصنف]],'اكواد الاصناف'!A:C,2,0),"") | D22: =IFERROR(VLOOKUP(Table3[[#This Row],[كود الصنف]],'اكواد الاصناف'!A:C,3,0),"") | F22: =IF(SUMIF('اكواد الاصناف'!A:A,Table3[[#This Row],[كود الصنف]],'اكواد الاصناف'!D:D)=0,"",SUMIF('اكواد الاصناف'!A:A,Table3[[#This Row],[كود الصنف]],'اكواد الاصناف'!D:D)) | G22: =IFERROR(IF(Table3[[#This Row],[السعر]]*Table3[[#This Row],[الكمية]]<=0,"",Table3[[#This Row],[السعر]]*Table3[[#This Row],[الكمية]]),"")
... A25: 15 | C25: =IFERROR(VLOOKUP(Table3[[#This Row],[كود الصنف]],'اكواد الاصناف'!A:C,2,0),"") | D25: =IFERROR(VLOOKUP(Table3[[#This Row],[كود الصنف]],'اكواد الاصناف'!A:C,3,0),"") | F25: =IF(SUMIF('اكواد الاصناف'!A:A,Table3[[#This Row],[كود الصنف]],'اكواد الاصناف'!D:D)=0,"",SUMIF('اكواد الاصناف'!A:A,Table3[[#This Row],[كود الصنف]],'اكواد الاصناف'!D:D)) | G25: =IFERROR(IF(Table3[[#This Row],[السعر]]*Table3[[#This Row],[الكمية]]<=0,"",Table3[[#This Row],[السعر]]*Table3[[#This Row],[الكمية]]),"")
B26: الاجمالي | G26: =SUBTOTAL(109,Table3[القيمة]) -> 0

Sheet سجل المبيعات
A1: م | B1: كود الصنف | C1: اسم الصنف | D1: الوحدة | E1: الكمية | F1: السعر | G1: القيمة | H1: كود العميل | I1: اسم العميل | J1: رقم فاتورة البيع
A2: 1 | B2: 308 | C2: =IFERROR(VLOOKUP(B2,'اكواد الاصناف'!A:C,2,0),"") -> لبن بخيره لتر | D2: =IFERROR(VLOOKUP(B2,'اكواد الاصناف'!A:C,3,0),"") -> كرتونة | E2: 3 | F2: 460 | G2: =F2*E2 -> 1380 | H2: 33 | I2: =IFERROR(VLOOKUP(H2,'سجل العملاء'!A:B,2,0),"") -> محمود | J2: 517 | K2: 46174
A3: 2 | B3: 307 | C3: =IFERROR(VLOOKUP(B3,'اكواد الاصناف'!A:C,2,0),"") -> لبن بخيره 500 مل | D3: =IFERROR(VLOOKUP(B3,'اكواد الاصناف'!A:C,3,0),"") -> كرتونة | E3: 3 | F3: 505 | G3: =F3*E3 -> 1515 | H3: 33 | I3: =IFERROR(VLOOKUP(H3,'سجل العملاء'!A:B,2,0),"") -> محمود | J3: 517
A4: 3 | B4: 571 | C4: =IFERROR(VLOOKUP(B4,'اكواد الاصناف'!A:C,2,0),"") -> صلصة هارفست ظرف 30جم | D4: =IFERROR(VLOOKUP(B4,'اكواد الاصناف'!A:C,3,0),"") -> علبة | E4: 4 | F4: 200 | G4: =F4*E4 -> 800 | H4: 33 | I4: =IFERROR(VLOOKUP(H4,'سجل العملاء'!A:B,2,0),"") -> محمود | J4: 517
A5: 4 | B5: 227 | C5: =IFERROR(VLOOKUP(B5,'اكواد الاصناف'!A:C,2,0),"") -> بن فكاكيس 100 جم | D5: =IFERROR(VLOOKUP(B5,'اكواد الاصناف'!A:C,3,0),"") -> بالتة | E5: 2 | F5: 470 | G5: =F5*E5 -> 940 | H5: 33 | I5: =IFERROR(VLOOKUP(H5,'سجل العملاء'!A:B,2,0),"") -> محمود | J5: 517
A6: 5 | B6: 70 | C6: =IFERROR(VLOOKUP(B6,'اكواد الاصناف'!A:C,2,0),"") -> زيت سلايت عباد 700 مل | D6: =IFERROR(VLOOKUP(B6,'اكواد الاصناف'!A:C,3,0),"") -> كرتونة | E6: 2 | F6: 850 | G6: =F6*E6 -> 1700 | H6: 33 | I6: =IFERROR(VLOOKUP(H6,'سجل العملاء'!A:B,2,0),"") -> محمود | J6: 517
A7: 6 | B7: 220 | C7: =IFERROR(VLOOKUP(B7,'اكواد الاصناف'!A:C,2,0),"") -> شاى العروسة 100 جم | D7: =IFERROR(VLOOKUP(B7,'اكواد الاصناف'!A:C,3,0),"") -> كيلو | E7: 2 | F7: 212.5 | G7: =F7*E7 -> 425 | H7: 33 | I7: =IFERROR(VLOOKUP(H7,'سجل العملاء'!A:B,2,0),"") -> محمود | J7: 517
A8: 7 | B8: 221 | C8: =IFERROR(VLOOKUP(B8,'اكواد الاصناف'!A:C,2,0),"") -> شاى العروسة 40 جم | D8: =IFERROR(VLOOKUP(B8,'اكواد الاصناف'!A:C,3,0),"") -> كيلو | E8: 2 | F8: 212.5 | G8: =F8*E8 -> 425 | H8: 33 | I8: =IFERROR(VLOOKUP(H8,'سجل العملاء'!A:B,2,0),"") -> محمود | J8: 517
A9: 8 | B9: 27 | C9: =IFERROR(VLOOKUP(B9,'اكواد الاصناف'!A:C,2,0),"") -> ملح الخير 225 جم * 20 كيس | D9: =IFERROR(VLOOKUP(B9,'اكواد الاصناف'!A:C,3,0),"") -> بالتة | E9: 10 | F9: 29.5 | G9: =F9*E9 -> 295 | H9: 33 | I9: =IFERROR(VLOOKUP(H9,'سجل العملاء'!A:B,2,0),"") -> محمود | J9: 517
A10: 9 | B10: 355 | C10: =IFERROR(VLOOKUP(B10,'اكواد الاصناف'!A:C,2,0),"") -> بيبسى 2.5 لتر | D10: =IFERROR(VLOOKUP(B10,'اكواد الاصناف'!A:C,3,0),"") -> بالتة | E10: 3 | F10: 220 | G10: =F10*E10 -> 660 | H10: 33 | I10: =IFERROR(VLOOKUP(H10,'سجل العملاء'!A:B,2,0),"") -> محمود | J10: 517
A11: 10 | B11: 356 | C11: =IFERROR(VLOOKUP(B11,'اكواد الاصناف'!A:C,2,0),"") -> سفن اب 2.5 لتر | D11: =IFERROR(VLOOKUP(B11,'اكواد الاصناف'!A:C,3,0),"") -> بالتة | E11: 3 | F11: 220 | G11: =F11*E11 -> 660 | H11: 33 | I11: =IFERROR(VLOOKUP(H11,'سجل العملاء'!A:B,2,0),"") -> محمود | J11: 517
A12: 11 | B12: 191 | C12: =IFERROR(VLOOKUP(B12,'اكواد الاصناف'!A:C,2,0),"") -> نسكافيه 3*1 شيكولاته | D12: =IFERROR(VLOOKUP(B12,'اكواد الاصناف'!A:C,3,0),"") -> علبة | E12: 2 | F12: 135 | G12: =F12*E12 -> 270 | H12: 33 | I12: =IFERROR(VLOOKUP(H12,'سجل العملاء'!A:B,2,0),"") -> محمود | J12: 517
A13: 12 | B13: 190 | C13: =IFERROR(VLOOKUP(B13,'اكواد الاصناف'!A:C,2,0),"") -> نسكافيه 3*1 | D13: =IFERROR(VLOOKUP(B13,'اكواد الاصناف'!A:C,3,0),"") -> علبة | E13: 2 | F13: 135 | G13: =F13*E13 -> 270 | H13: 33 | I13: =IFERROR(VLOOKUP(H13,'سجل العملاء'!A:B,2,0),"") -> محمود | J13: 517
A14: 13 | B14: 192 | C14: =IFERROR(VLOOKUP(B14,'اكواد الاصناف'!A:C,2,0),"") -> نسكافيه 3*1 كراميل | D14: =IFERROR(VLOOKUP(B14,'اكواد الاصناف'!A:C,3,0),"") -> علبة | E14: 2 | F14: 135 | G14: =F14*E14 -> 270 | H14: 33 | I14: =IFERROR(VLOOKUP(H14,'سجل العملاء'!A:B,2,0),"") -> محمود | J14: 517
A15: 14 | B15: 447 | C15: =IFERROR(VLOOKUP(B15,'اكواد الاصناف'!A:C,2,0),"") -> فلفل برازيلي حصي | D15: =IFERROR(VLOOKUP(B15,'اكواد الاصناف'!A:C,3,0),"") -> كيلو | E15: 2 | F15: 405 | G15: =F15*E15 -> 810 | H15: 33 | I15: =IFERROR(VLOOKUP(H15,'سجل العملاء'!A:B,2,0),"") -> محمود | J15: 517
A16: 15 | B16: 489 | C16: =IFERROR(VLOOKUP(B16,'اكواد الاصناف'!A:C,2,0),"") -> حلبة بلدي | D16: =IFERROR(VLOOKUP(B16,'اكواد الاصناف'!A:C,3,0),"") -> كيلو | F16: 38 | G16: =F16*E16 -> 0 | H16: 33 | I16: =IFERROR(VLOOKUP(H16,'سجل العملاء'!A:B,2,0),"") -> محمود | J16: 517
A17: 16 | B17: 572 | C17: =IFERROR(VLOOKUP(B17,'اكواد الاصناف'!A:C,2,0),"") -> زبيب أحفاد سعد الجمل 5 ك | D17: =IFERROR(VLOOKUP(B17,'اكواد الاصناف'!A:C,3,0),"") -> كرتونة | E17: 1 | F17: 900 | G17: =F17*E17 -> 900 | H17: 33 | I17: =IFERROR(VLOOKUP(H17,'سجل العملاء'!A:B,2,0),"") -> محمود | J17: 517
A18: 17 | B18: 573 | C18: =IFERROR(VLOOKUP(B18,'اكواد الاصناف'!A:C,2,0),"") -> حلبة محوجه | D18: =IFERROR(VLOOKUP(B18,'اكواد الاصناف'!A:C,3,0),"") -> كيلو | E18: 2 | F18: 80 | G18: =F18*E18 -> 160 | H18: 33 | I18: =IFERROR(VLOOKUP(H18,'سجل العملاء'!A:B,2,0),"") -> محمود | J18: 517
A19: 1 | B19: 31 | C19: =IFERROR(VLOOKUP(B19,'اكواد الاصناف'!A:C,2,0),"") -> مكرونة جواهر 10ك هلالية | D19: =IFERROR(VLOOKUP(B19,'اكواد الاصناف'!A:C,3,0),"") -> شيكارة | E19: 1 | F19: 218 | G19: =F19*E19 -> 218 | H19: 75 | I19: =IFERROR(VLOOKUP(H19,'سجل العملاء'!A:B,2,0),"") -> الحمد | J19: 518
A20: 2 | B20: 35 | C20: =IFERROR(VLOOKUP(B20,'اكواد الاصناف'!A:C,2,0),"") -> مكرونة جواهر 10ك اسباجتى | D20: =IFERROR(VLOOKUP(B20,'اكواد الاصناف'!A:C,3,0),"") -> شيكارة | E20: 1 | F20: 218 | G20: =F20*E20 -> 218 | H20: 75 | I20: =IFERROR(VLOOKUP(H20,'سجل العملاء'!A:B,2,0),"") -> الحمد | J20: 518
A21: 3 | B21: 33 | C21: =IFERROR(VLOOKUP(B21,'اكواد الاصناف'!A:C,2,0),"") -> مكرونة جواهر 10ك فرن | D21: =IFERROR(VLOOKUP(B21,'اكواد الاصناف'!A:C,3,0),"") -> شيكارة | E21: 1 | F21: 218 | G21: =F21*E21 -> 218 | H21: 75 | I21: =IFERROR(VLOOKUP(H21,'سجل العملاء'!A:B,2,0),"") -> الحمد | J21: 518
A22: 4 | B22: 100 | C22: =IFERROR(VLOOKUP(B22,'اكواد الاصناف'!A:C,2,0),"") -> سمنة جنة نيوزيلندى 700 جم | D22: =IFERROR(VLOOKUP(B22,'اكواد الاصناف'!A:C,3,0),"") -> كرتونة | E22: 1 | F22: 703 | G22: =F22*E22 -> 703 | H22: 75 | I22: =IFERROR(VLOOKUP(H22,'سجل العملاء'!A:B,2,0),"") -> الحمد | J22: 518
A23: 5 | B23: 121 | C23: =IFERROR(VLOOKUP(B23,'اكواد الاصناف'!A:C,2,0),"") -> صلصة هاينز برطمان | D23: =IFERROR(VLOOKUP(B23,'اكواد الاصناف'!A:C,3,0),"") -> بالتة | E23: 1 | F23: 395 | G23: =F23*E23 -> 395 | H23: 75 | I23: =IFERROR(VLOOKUP(H23,'سجل العملاء'!A:B,2,0),"") -> الحمد | J23: 518
A24: 6 | B24: 571 | C24: =IFERROR(VLOOKUP(B24,'اكواد الاصناف'!A:C,2,0),"") -> صلصة هارفست ظرف 30جم | D24: =IFERROR(VLOOKUP(B24,'اكواد الاصناف'!A:C,3,0),"") -> علبة | F24: 200 | G24: =F24*E24 -> 0 | H24: 75 | I24: =IFERROR(VLOOKUP(H24,'سجل العملاء'!A:B,2,0),"") -> الحمد | J24: 518
A25: 7 | B25: 131 | C25: =IFERROR(VLOOKUP(B25,'اكواد الاصناف'!A:C,2,0),"") -> صلصة روسو صفيح 800 جم | D25: =IFERROR(VLOOKUP(B25,'اكواد الاصناف'!A:C,3,0),"") -> بالتة | E25: 1 | F25: 440 | G25: =F25*E25 -> 440 | H25: 75 | I25: =IFERROR(VLOOKUP(H25,'سجل العملاء'!A:B,2,0),"") -> الحمد | J25: 518
A26: 8 | B26: 135 | C26: =IFERROR(VLOOKUP(B26,'اكواد الاصناف'!A:C,2,0),"") -> كاتشب هاينز ظرف كبير | D26: =IFERROR(VLOOKUP(B26,'اكواد الاصناف'!A:C,3,0),"") -> علبة | E26: 1 | F26: 158 | G26: =F26*E26 -> 158 | H26: 75 | I26: =IFERROR(VLOOKUP(H26,'سجل العملاء'!A:B,2,0),"") -> الحمد | J26: 518
A27: 9 | B27: 145 | C27: =IFERROR(VLOOKUP(B27,'اكواد الاصناف'!A:C,2,0),"") -> خل هاينز لتر | D27: =IFERROR(VLOOKUP(B27,'اكواد الاصناف'!A:C,3,0),"") -> بالتة | E27: 1 | F27: 230 | G27: =F27*E27 -> 230 | H27: 75 | I27: =IFERROR(VLOOKUP(H27,'سجل العملاء'!A:B,2,0),"") -> الحمد | J27: 518
A28: 10 | B28: 147 | C28: =IFERROR(VLOOKUP(B28,'اكواد الاصناف'!A:C,2,0),"") -> مرقة دجاج كنور 12 مكعب | D28: =IFERROR(VLOOKUP(B28,'اكواد الاصناف'!A:C,3,0),"") -> بالتة | E28: 1 | F28: 161 | G28: =F28*E28 -> 161 | H28: 75 | I28: =IFERROR(VLOOKUP(H28,'سجل العملاء'!A:B,2,0),"") -> الحمد | J28: 518
A29: 11 | B29: 155 | C29: =IFERROR(VLOOKUP(B29,'اكواد الاصناف'!A:C,2,0),"") -> خلطة بشاميل فاين فودز سادة | D29: =IFERROR(VLOOKUP(B29,'اكواد الاصناف'!A:C,3,0),"") -> علبة | E29: 1 | F29: 160 | G29: =F29*E29 -> 160 | H29: 75 | I29: =IFERROR(VLOOKUP(H29,'سجل العملاء'!A:B,2,0),"") -> الحمد | J29: 518
A30: 12 | B30: 158 | C30: =IFERROR(VLOOKUP(B30,'اكواد الاصناف'!A:C,2,0),"") -> تتبيلة برجر ويلز | D30: =IFERROR(VLOOKUP(B30,'اكواد الاصناف'!A:C,3,0),"") -> علبة | E30: 1 | F30: 71 | G30: =F30*E30 -> 71 | H30: 75 | I30: =IFERROR(VLOOKUP(H30,'سجل العملاء'!A:B,2,0),"") -> الحمد | J30: 518
A31: 13 | B31: 162 | C31: =IFERROR(VLOOKUP(B31,'اكواد الاصناف'!A:C,2,0),"") -> تتبيلة كفتة ويلز | D31: =IFERROR(VLOOKUP(B31,'اكواد الاصناف'!A:C,3,0),"") -> علبة | E31: 1 | F31: 71 | G31: =F31*E31 -> 71 | H31: 75 | I31: =IFERROR(VLOOKUP(H31,'سجل العملاء'!A:B,2,0),"") -> الحمد | J31: 518
A32: 14 | B32: 163 | C32: =IFERROR(VLOOKUP(B32,'اكواد الاصناف'!A:C,2,0),"") -> تتبيلة شاورما سوري ويلز | D32: =IFERROR(VLOOKUP(B32,'اكواد الاصناف'!A:C,3,0),"") -> علبة | E32: 1 | F32: 71 | G32: =F32*E32 -> 71 | H32: 75 | I32: =IFERROR(VLOOKUP(H32,'سجل العملاء'!A:B,2,0),"") -> الحمد | J32: 518
A33: 15 | B33: 193 | C33: =IFERROR(VLOOKUP(B33,'اكواد الاصناف'!A:C,2,0),"") -> نسكافيه 3*1 بندق | D33: =IFERROR(VLOOKUP(B33,'اكواد الاصناف'!A:C,3,0),"") -> علبة | E33: 1 | F33: 135 | G33: =F33*E33 -> 135 | H33: 75 | I33: =IFERROR(VLOOKUP(H33,'سجل العملاء'!A:B,2,0),"") -> الحمد | J33: 518
A34: 16 | B34: 208 | C34: =IFERROR(VLOOKUP(B34,'اكواد الاصناف'!A:C,2,0),"") -> تانج مانجو 25جم | D34: =IFERROR(VLOOKUP(B34,'اكواد الاصناف'!A:C,3,0),"") -> علبة | E34: 1 | F34: 95 | G34: =F34*E34 -> 95 | H34: 75 | I34: =IFERROR(VLOOKUP(H34,'سجل العملاء'!A:B,2,0),"") -> الحمد | J34: 518
A35: 17 | B35: 309 | C35: =IFERROR(VLOOKUP(B35,'اكواد الاصناف'!A:C,2,0),"") -> لبن جهينة لتر كامل الدسم | D35: =IFERROR(VLOOKUP(B35,'اكواد الاصناف'!A:C,3,0),"") -> بالتة | E35: 1 | F35: 562 | G35: =F35*E35 -> 562 | H35: 75 | I35: =IFERROR(VLOOKUP(H35,'سجل العملاء'!A:B,2,0),"") -> الحمد | J35: 518
A36: 18 | B36: 324 | C36: =IFERROR(VLOOKUP(B36,'اكواد الاصناف'!A:C,2,0),"") -> عصير جهينة لتر تفاح | D36: =IFERROR(VLOOKUP(B36,'اكواد الاصناف'!A:C,3,0),"") -> بالتة | E36: 1 | F36: 360 | G36: =F36*E36 -> 360 | H36: 75 | I36: =IFERROR(VLOOKUP(H36,'سجل العملاء'!A:B,2,0),"") -> الحمد | J36: 518
... A111: 9 | B111: 160 | C111: =IFERROR(VLOOKUP(B111,'اكواد الاصناف'!A:C,2,0),"") -> تتبيلة بشاميل كريمة ويلز | D111: =IFERROR(VLOOKUP(B111,'اكواد الاصناف'!A:C,3,0),"") -> علبة | E111: 1 | F111: 71 | G111: =F111*E111 -> 71 | H111: 25 | I111: =IFERROR(VLOOKUP(H111,'سجل العملاء'!A:B,2,0),"") -> الحرمين ماركت | J111: 524
A112: 10 | B112: 27 | C112: =IFERROR(VLOOKUP(B112,'اكواد الاصناف'!A:C,2,0),"") -> ملح الخير 225 جم * 20 كيس | D112: =IFERROR(VLOOKUP(B112,'اكواد الاصناف'!A:C,3,0),"") -> بالتة | F112: 29.5 | G112: =F112*E112 -> 0 | H112: 25 | I112: =IFERROR(VLOOKUP(H112,'سجل العملاء'!A:B,2,0),"") -> الحرمين ماركت | J112: 524
A113: 11 | B113: 251 | C113: =IFERROR(VLOOKUP(B113,'اكواد الاصناف'!A:C,2,0),"") -> جبنة رودس سادة 500 جم | D113: =IFERROR(VLOOKUP(B113,'اكواد الاصناف'!A:C,3,0),"") -> بالتة | E113: 1 | F113: 515 | G113: =F113*E113 -> 515 | H113: 25 | I113: =IFERROR(VLOOKUP(H113,'سجل العملاء'!A:B,2,0),"") -> الحرمين ماركت | J113: 524
A114: 12 | B114: 90 | C114: =IFERROR(VLOOKUP(B114,'اكواد الاصناف'!A:C,2,0),"") -> زيت ممتاز 700 مل | D114: =IFERROR(VLOOKUP(B114,'اكواد الاصناف'!A:C,3,0),"") -> كرتونة | E114: 1 | F114: 650 | G114: =F114*E114 -> 650 | H114: 25 | I114: =IFERROR(VLOOKUP(H114,'سجل العملاء'!A:B,2,0),"") -> الحرمين ماركت | J114: 524
...

Sheet اجمالي المشتريات
A1: التاريخ | B1: المشتريات
A2: 46174 | B2: فاتورة الزهراء (انستا) | E2: 17658
A3: 46175 | B3: فاتورة الزهراء (انستا) | E3: 8895
A4: 46175 | B4: فاتورة العروسة | E4: 24170
A5: 46176 | B5: فاتورة الزهراء | E5: 16465

Sheet اجمالي المصروفات
A1: التاريخ | B1: المصروفات
A2: 46174 | B2: زيت باور | E2: 430
A3: 46174 | B3: شامبو | E3: 200
A4: 46174 | B4: محمد سلفه | E4: 200
A5: 46175 | B5: غرامة مخالفه | E5: 50
A6: 46175 | B6: شامبو | E6: 200
A7: 46176 | B7: شامبو | E7: 200

Sheet الاجماليات
B2: اجمالي المصروفات | F2: اجمالي المشتريات | J2: اجمالي المبيعات
B4: =SUM('اجمالي المصروفات'!E:E) -> 1280 | F4: =SUM('اجمالي المشتريات'!E:E) -> 67188 | J4: =SUM('سجل المبيعات'!G2:'سجل المبيعات'!G15029) -> 469687.02
B7: صافي الربح
B9: =J4-F4-B4 -> 401219.02
